Workbook

Sheet Tổng quan
A1: REVIEW CỜ TỶ PHÚ 3D – game-tuoi-tho.vercel.app
A2: Ngày review: 29/10/2026 · Chế độ test: Đấu với Bot (1 Bot) · ~13 lượt chơi · Trình duyệt Chrome desktop
A4: Thang mức độ
A5: P0 | B5: Lỗi chặn / sai luật – sửa ngay trước mọi việc khác
A6: P1 | B6: Ảnh hưởng mạnh trải nghiệm – sprint kế tiếp
A7: P2 | B7: Nâng cấp chất lượng – nên làm
A8: P3 | B8: Chi tiết nhỏ – làm khi rảnh
A10: Thống kê theo nhóm (tự cập nhật theo sheet 'Danh sách hạng mục')
A11: Nhóm | B11: P0 | C11: P1 | D11: P2 | E11: P3 | F11: Tổng | G11: Đã xong
A12: Lỗi gameplay | B12: =COUNTIFS('Danh sách hạng mục'!$B$2:$B$41,$A12,'Danh sách hạng mục'!$D$2:$D$41,"P0") -> 4 | C12: =COUNTIFS('Danh sách hạng mục'!$B$2:$B$41,$A12,'Danh sách hạng mục'!$D$2:$D$41,"P1") -> 1 | D12: =COUNTIFS('Danh sách hạng mục'!$B$2:$B$41,$A12,'Danh sách hạng mục'!$D$2:$D$41,"P2") -> 0 | E12: =COUNTIFS('Danh sách hạng mục'!$B$2:$B$41,$A12,'Danh sách hạng mục'!$D$2:$D$41,"P3") -> 0 | F12: =SUM(B12:E12) -> 5 | G12: =COUNTIFS('Danh sách hạng mục'!$B$2:$B$41,$A12,'Danh sách hạng mục'!$I$2:$I$41,"Đã xong") -> 0
A13: Gameplay & cân bằng | B13: =COUNTIFS('Danh sách hạng mục'!$B$2:$B$41,$A13,'Danh sách hạng mục'!$D$2:$D$41,"P0") -> 0 | C13: =COUNTIFS('Danh sách hạng mục'!$B$2:$B$41,$A13,'Danh sách hạng mục'!$D$2:$D$41,"P1") -> 3 | D13: =COUNTIFS('Danh sách hạng mục'!$B$2:$B$41,$A13,'Danh sách hạng mục'!$D$2:$D$41,"P2") -> 5 | E13: =COUNTIFS('Danh sách hạng mục'!$B$2:$B$41,$A13,'Danh sách hạng mục'!$D$2:$D$41,"P3") -> 1 | F13: =SUM(B13:E13) -> 9 | G13: =COUNTIFS('Danh sách hạng mục'!$B$2:$B$41,$A13,'Danh sách hạng mục'!$I$2:$I$41,"Đã xong") -> 0
A14: Giao diện (UI/UX) | B14: =COUNTIFS('Danh sách hạng mục'!$B$2:$B$41,$A14,'Danh sách hạng mục'!$D$2:$D$41,"P0") -> 0 | C14: =COUNTIFS('Danh sách hạng mục'!$B$2:$B$41,$A14,'Danh sách hạng mục'!$D$2:$D$41,"P1") -> 4 | D14: =COUNTIFS('Danh sách hạng mục'!$B$2:$B$41,$A14,'Danh sách hạng mục'!$D$2:$D$41,"P2") -> 5 | E14: =COUNTIFS('Danh sách hạng mục'!$B$2:$B$41,$A14,'Danh sách hạng mục'!$D$2:$D$41,"P3") -> 2 | F14: =SUM(B14:E14) -> 11 | G14: =COUNTIFS('Danh sách hạng mục'!$B$2:$B$41,$A14,'Danh sách hạng mục'!$I$2:$I$41,"Đã xong") -> 0
A15: Đồ họa 3D | B15: =COUNTIFS('Danh sách hạng mục'!$B$2:$B$41,$A15,'Danh sách hạng mục'!$D$2:$D$41,"P0") -> 0 | C15: =COUNTIFS('Danh sách hạng mục'!$B$2:$B$41,$A15,'Danh sách hạng mục'!$D$2:$D$41,"P1") -> 4 | D15: =COUNTIFS('Danh sách hạng mục'!$B$2:$B$41,$A15,'Danh sách hạng mục'!$D$2:$D$41,"P2") -> 5 | E15: =COUNTIFS('Danh sách hạng mục'!$B$2:$B$41,$A15,'Danh sách hạng mục'!$D$2:$D$41,"P3") -> 0 | F15: =SUM(B15:E15) -> 9 | G15: =COUNTIFS('Danh sách hạng mục'!$B$2:$B$41,$A15,'Danh sách hạng mục'!$I$2:$I$41,"Đã xong") -> 0
A16: Animation | B16: =COUNTIFS('Danh sách hạng mục'!$B$2:$B$41,$A16,'Danh sách hạng mục'!$D$2:$D$41,"P0") -> 0 | C16: =COUNTIFS('Danh sách hạng mục'!$B$2:$B$41,$A16,'Danh sách hạng mục'!$D$2:$D$41,"P1") -> 3 | D16: =COUNTIFS('Danh sách hạng mục'!$B$2:$B$41,$A16,'Danh sách hạng mục'!$D$2:$D$41,"P2") -> 3 | E16: =COUNTIFS('Danh sách hạng mục'!$B$2:$B$41,$A16,'Danh sách hạng mục'!$D$2:$D$41,"P3") -> 0 | F16: =SUM(B16:E16) -> 6 | G16: =COUNTIFS('Danh sách hạng mục'!$B$2:$B$41,$A16,'Danh sách hạng mục'!$I$2:$I$41,"Đã xong") -> 0
A17: TỔNG | B17: =SUM(B12:B16) -> 4 | C17: =SUM(C12:C16) -> 15 | D17: =SUM(D12:D16) -> 18 | E17: =SUM(E12:E16) -> 3 | F17: =SUM(F12:F16) -> 40 | G17: =SUM(G12:G16) -> 0
A19: Thứ tự đề xuất cho Antigravity
A20: Sprint 1 (P0): BUG-01 → BUG-05 – sửa logic mua ô, thẻ di chuyển, thưởng đổ đôi, đồng hồ lượt. Viết unit test cho từng luật.
A21: Sprint 2 (khả năng nhìn thấy): VIS-01, VIS-02, VIS-03, UI-01, UI-02, UI-03 – người chơi phải thấy toàn bộ bàn, quân và ai sở hữu ô nào.
A22: Sprint 3 (cảm giác chơi): ANI-01, ANI-02, ANI-04, GP-03, GP-04, UI-04 + cân bằng kinh tế GP-01, GP-02.
A23: Sprint 4 (hoàn thiện): các hạng mục P2/P3 còn lại, art direction VIS-08, cài đặt ván GP-05.
A24: Sau mỗi sprint: test lại các mục ở sheet 'Chưa kiểm tra'.

Sheet Danh sách hạng mục
A1: Mã | B1: Nhóm | C1: Hạng mục | D1: Mức độ | E1: Hiện trạng / cách tái hiện | F1: Yêu cầu sửa / tiêu chí nghiệm thu | G1: Gợi ý kỹ thuật | H1: Kiểm chứng | I1: Trạng thái | J1: Ghi chú của Long
A2: BUG-01 | B2: Lỗi gameplay | C2: Không mua được ô Giao thông & Tiện ích (người chơi) | D2: P0 | E2: Dừng tại Sân Bay Nội Bài [27] và Trạm Cấp Nước Sạch [20] → bấm 'MUA ĐẤT & XÂY DỰNG' không có phản hồi: tiền không trừ, modal không đóng, nhật ký không ghi. Chỉ thoát được bằng 'Bỏ Qua'. Bot vẫn mua được chính các ô này (Bot mua Nội Bài, Tân Sơn Nhất, Bến Xe Miền Đông). | F2: Người chơi mua được mọi ô có giá (bất động sản, sân bay, bến xe, cảng, nhà máy điện, trạm nước). Sau khi mua: trừ tiền, ghi nhật ký, đánh dấu chủ sở hữu trên bàn, đóng modal. | G2: Kiểm tra handler nút mua trong modal: nhiều khả năng điều kiện chỉ xử lý type 'property' hoặc phụ thuộc cấp nâng cấp đang chọn (các cấp khác 'Không áp dụng'). Dùng chung hàm buyTile() mà Bot đang gọi. | H2: Đã tái hiện 2/2 lần | I2: Chưa làm
A3: BUG-02 | B3: Lỗi gameplay | C3: Không hiện modal mua khi dừng ở một số ô Giao thông/Tiện ích | D3: P0 | E3: Dừng tại Bến Xe Mỹ Đình [21] (sau khi đổ đôi 6-6) và Nhà Máy Điện [4]: nhật ký ghi 'chưa có chủ sở hữu. Giá bán…' nhưng không có modal mua, chỉ có nút 'Kết thúc lượt' → mất quyền mua. | F3: Mọi ô chưa có chủ đều bật modal Mua / Bỏ qua cho người chơi, kể cả trong lượt đổ đôi. | G3: Rà luồng state machine sau khi di chuyển: LANDED → PROMPT_BUY. Kiểm tra nhánh doubles và nhánh tile.type ≠ property. | H3: Đã tái hiện 2 lần, cần dev xác minh nguyên nhân chung với BUG-01 | I3: Chưa làm
A4: BUG-03 | B4: Lỗi gameplay | C4: Thẻ di chuyển không kích hoạt hiệu ứng ô đến | D4: P0 | E4: Bot rút thẻ 'Về thăm Cố Đô Huế' (bay tới ô #15) → quân được dời tới Huế (ô người chơi đang sở hữu) nhưng KHÔNG trả tiền thuê, nhật ký không ghi gì. Tương tự thẻ 'Tiến về Sài Gòn lập nghiệp' (#31): không có đề nghị mua TP.HCM. | F4: Sau khi thẻ di chuyển quân: chạy đầy đủ xử lý ô đến (thu thuê / mua / rút thẻ…), cộng 200.000đ nếu đi qua Cổng Làng, ghi nhật ký 'X bay tới …'. | G4: Sau moveTo(cardTarget) gọi lại resolveLanding(tile). Tính passGo khi targetIndex < currentIndex. | H4: Đã kiểm chứng qua nhật ký (vị trí lượt sau khớp ô 15 và 31) | I4: Chưa làm
A5: BUG-04 | B5: Lỗi gameplay | C5: Thưởng đổ đôi +50.000đ không được cộng | D5: P0 | E5: Luật chơi ghi: đổ đôi nhận ngay +50.000đ. Thực tế: người chơi đổ [6,6] nhưng tiền = 2.000k − 120k = 1.880k (không có +50k). Bot đổ [5,5]: 1.900k + 50k (Quỹ Heo) − 200k = 1.750k (không có +50k). | F5: Hoặc cộng +50.000đ mỗi lần đổ đôi và ghi nhật ký, hoặc bỏ dòng này khỏi Luật chơi. Luật và code phải khớp nhau. | G5: Thêm bonus trong onDiceRolled khi d1===d2. | H5: Đã kiểm chứng bằng phép tính số dư | I5: Chưa làm
A6: BUG-05 | B6: Lỗi gameplay | C6: Đồng hồ lượt hết giờ nhưng không có tác dụng | D6: P1 | E6: Modal mua Sân Bay Nội Bài bị kẹt hơn 60 giây, đồng hồ lượt (60s) hết nhưng game đứng yên. | F6: Hết giờ → tự động 'Bỏ qua' modal và kết thúc lượt. Ở chế độ chơi với Bot cho phép tắt đồng hồ trong cài đặt. | G6: Timer onExpire → dispatch(SKIP_ACTION) + END_TURN. | H6: Đã tái hiện 1 lần | I6: Chưa làm
A7: GP-01 | B7: Gameplay & cân bằng | C7: Nâng cấp quá dễ, tiền thuê tăng đột biến | D7: P1 | E7: Quay lại Cảng Hải Phòng (giá đất 320k) là được nâng ngay lên Nhà phố, không cần sở hữu trọn bộ màu. Tiền thuê nhảy 32.000đ → 160.000đ (x5) với chi phí 240.000đ — hoàn vốn sau ~1,5 lần đối thủ ghé. | F7: Chỉ cho xây nhà khi sở hữu trọn bộ màu (như Monopoly gốc) HOẶC giữ luật hiện tại nhưng giảm hệ số: Đất 10% → Nhà phố ~25% → Chung cư ~60% → Khách sạn ~120% giá đất. Đưa bảng giá thuê vào file config để dễ chỉnh. | G7: Tách bảng giá thuê ra constants/economy.ts; thêm canBuild(tile, player) kiểm tra color set. | H7: Đã kiểm chứng | I7: Chưa làm
A8: GP-02 | B8: Gameplay & cân bằng | C8: Tiền thuê Giao thông không tăng theo số ô sở hữu | D8: P2 | E8: Bot sở hữu 3 ô giao thông (Nội Bài, Tân Sơn Nhất, Miền Đông) nhưng người chơi dừng ở Tân Sơn Nhất chỉ trả 25.000đ (giá cơ bản). | F8: Thuê giao thông theo số ô sở hữu: 1 ô 25k – 2 ô 50k – 3 ô 100k – 4 ô 200k. Tiện ích (Điện/Nước): thuê = tổng xúc xắc × 4 (1 ô) hoặc × 10 (2 ô). | H8: Đã kiểm chứng | I8: Chưa làm
A9: GP-03 | B9: Gameplay & cân bằng | C9: Nút 'KẾT THÚC LƯỢT' sai nghĩa khi đổ đôi | D9: P1 | E9: Sau khi đổ đôi, panel hiện 'SỐ ĐÔI! ĐƯỢC ĐỔ THÊM LƯỢT' nhưng nút lại ghi 'KẾT THÚC LƯỢT' (thực tế bấm vào là được đổ tiếp). Gây hiểu nhầm, người chơi sợ mất lượt. | F9: Khi đang trong chuỗi đổ đôi: nút ghi 'ĐỔ TIẾP 🎲'. Chỉ hiện 'Kết thúc lượt' khi thật sự hết lượt. | H9: Đã kiểm chứng | I9: Chưa làm
A10: GP-04 | B10: Gameplay & cân bằng | C10: Bot đánh quá nhanh, người chơi không theo dõi được | D10: P1 | E10: Toàn bộ lượt Bot (2 lần đổ do đổ đôi + ăn Quỹ Heo + mua đất) diễn ra trong ~4 giây, camera không bám theo, quân Bot thường bị khuất sau núi/HUD. | F10: Mỗi hành động của Bot có nhịp tối thiểu 0,8–1,2s, camera bám quân đang đi, hiển thị bong bóng 'Bot đã mua Sân Bay Nội Bài -200k'. Thêm tùy chọn tốc độ Bot (Chậm/Vừa/Nhanh). | G10: Hàng đợi action có await delay; camera lerp tới token đang active. | H10: Đã quan sát | I10: Chưa làm
A11: GP-05 | B11: Gameplay & cân bằng | C11: Thiếu cài đặt ván chơi | D11: P2 | E11: Màn 'Chọn chế độ chơi' chỉ có số người/số Bot và linh vật. Luật nhắc 'nếu ván chơi giới hạn số vòng' nhưng không có chỗ cài. Không có độ khó Bot. | F11: Thêm: Tiền khởi điểm (1.000k/2.000k/3.000k), Giới hạn vòng (Không giới hạn/15/25/40), Độ khó Bot (Dễ/Thường/Khó), Tốc độ animation, Bật/tắt đồng hồ lượt. | H11: Đã kiểm tra màn hình setup | I11: Chưa làm
A12: GP-06 | B12: Gameplay & cân bằng | C12: Không có đấu giá khi bỏ qua mua; thao tác 'Bỏ qua' không ghi nhật ký | D12: P2 | E12: Bấm 'Bỏ Qua' ô Sân Bay Nội Bài: không có dòng nhật ký nào, không có đấu giá. | F12: Ghi nhật ký 'X bỏ qua …'. (Tùy chọn) mở đấu giá nhanh cho các người chơi còn lại. | H12: Đã kiểm chứng | I12: Chưa làm
A13: GP-07 | B13: Gameplay & cân bằng | C13: Quản lý tài sản chỉ truy cập được khi đứng trên ô của mình | D13: P2 | E13: Tab 'Thế chấp / Bán nhà' chỉ xuất hiện trong modal khi dừng lại đúng ô mình sở hữu. Không có màn xem danh sách tài sản, không giao dịch giữa người chơi. | F13: Bấm vào thẻ người chơi → mở panel tài sản: danh sách ô, cấp nhà, tiền thuê hiện tại, nút Thế chấp/Bán/Giao dịch, dùng được bất kỳ lúc nào trong lượt của mình. | H13: Đã quan sát | I13: Chưa làm
A14: GP-08 | B14: Gameplay & cân bằng | C14: Bộ đếm 'Vòng' thực chất đếm lượt | D14: P2 | E14: Sau ~13 lượt (mỗi người chưa đi hết 2 vòng bàn cờ) header hiện 'Vòng 13'. Dễ hiểu nhầm với 'vòng bàn cờ' (đi qua Cổng Làng). | F14: Đổi nhãn thành 'Lượt 13' hoặc đếm đúng số vòng bàn cờ. Nếu có giới hạn vòng (GP-05) phải dùng đúng định nghĩa này. | H14: Đã quan sát | I14: Chưa làm
A15: GP-09 | B15: Gameplay & cân bằng | C15: Quỹ Heo Đất tự hồi về 20.000đ sau khi bị ăn | D15: P3 | E15: Bot ăn trọn Quỹ 50.000đ, ngay sau đó Quỹ hiển thị 20.000đ dù chưa ai nộp phạt. | F15: Nếu có cơ chế 'mồi quỹ' thì ghi rõ trong Luật + nhật ký; nếu không thì quỹ về 0. | H15: Cần dev xác minh có chủ đích hay không | I15: Chưa làm
A16: UI-01 | B16: Giao diện (UI/UX) | C16: HUD che mất bàn cờ | D16: P1 | E16: Thẻ người chơi che hàng ô phía trên; Nhật ký che cột trái (Bãi Sau Vũng Tàu, Bến Xe Miền Đông và quân đứng ở đó); panel xúc xắc che cột phải; mở Chat thì chồng lên Nhật ký → gần như cả cạnh trái bị che. | F16: Bố cục 'safe area': HUD nằm ngoài vùng chiếu của bàn cờ hoặc thu gọn được thành icon; camera fit bàn cờ với padding tính theo kích thước HUD. Không ô nào và không quân nào bị che ở góc nhìn mặc định (1366×768 và 1920×1080). | G16: Tính camera zoom dựa trên bounding box bàn cờ + viewport trừ HUD; Nhật ký/Chat dạng drawer. | H16: Đã quan sát nhiều lần | I16: Chưa làm
A17: UI-02 | B17: Giao diện (UI/UX) | C17: Không thấy ai sở hữu ô nào trên bàn cờ | D17: P1 | E17: Đã mua Nha Trang, Phú Quốc, Huế, Hạ Long, Hải Phòng; Bot mua Vũng Tàu, Nội Bài, Tràng An… nhưng trên bàn cờ không có cờ, viền màu hay nhà nào. Chỉ có các chấm màu nhỏ dưới thẻ người chơi. | F17: Ô đã mua: cắm cờ/viền màu theo màu người chơi + hiện tiền thuê hiện tại. Nâng cấp: hiện mô hình 3D tương ứng (nhà phố → chung cư → khách sạn). Hover/chạm ô → tooltip chủ sở hữu, cấp, tiền thuê. | H17: Đã kiểm chứng (zoom ảnh) | I17: Chưa làm
A18: UI-03 | B18: Giao diện (UI/UX) | C18: Modal mua đất/nâng cấp mở ngay khi bấm Đổ xúc xắc | D18: P1 | E18: Modal hiện ra trong khung hình đầu tiên sau khi bấm Đổ, trước khi xúc xắc và quân di chuyển xong; nền bị làm mờ nên người chơi không thấy mình đi tới đâu. | F18: Trình tự: xúc xắc lăn → dừng → quân nhảy từng ô → camera dừng ở ô đến (0,5s) → mới mở modal. | G18: await animationDone trước khi set modal state. | H18: Đã kiểm chứng bằng chụp màn hình liên tiếp | I18: Chưa làm
A19: UI-04 | B19: Giao diện (UI/UX) | C19: Popup kết quả xúc xắc ghi sai tên khi Bot đổ | D19: P1 | E19: Lượt Bot đổ 6+5 nhưng banner ghi 'KỲ THỦ NHÍ ĐÃ ĐỔ'. Banner còn che thẻ người chơi và trùng thông tin với panel xúc xắc góc phải. | F19: Banner dùng tên người đang đổ. Chỉ giữ 1 nơi hiển thị kết quả (đề xuất: xúc xắc 3D + số nổi trên bàn), bỏ banner trùng lặp. | H19: Đã kiểm chứng | I19: Chưa làm
A20: UI-05 | B20: Giao diện (UI/UX) | C20: Nội dung modal mua đất khó hiểu | D20: P2 | E20: 'Phí Xây Dựng' dùng cho giá mua đất; 'Giảm Phí 0đ' vô nghĩa; 'Phí Du Lịch Thu Về' = tiền thuê; icon ➡️ cạnh nhãn trông như lỗi; nút 'MUA ĐẤT & XÂY DỰNG' nhưng chỉ mua đất; có cả 'Bỏ Qua' và nút X làm cùng việc. Ô sân bay có phụ đề 'Bến Tàu Xe' và vẫn hiện 3 thẻ khóa 'Không áp dụng'. | F20: Đổi nhãn: 'Giá mua', 'Tiền thuê khi đối thủ ghé', 'Số dư sau khi mua'. Bỏ dòng Giảm phí nếu = 0. Ô giao thông/tiện ích dùng layout riêng (hiện bảng thuê theo số ô sở hữu). Nút chính: 'MUA – 200.000đ', nút phụ: 'Bỏ qua'. Bỏ nút X. | H20: Đã quan sát | I20: Chưa làm
A21: UI-06 | B21: Giao diện (UI/UX) | C21: Modal nâng cấp: nút bị xám không giải thích | D21: P2 | E21: Khi mở, thẻ được chọn sẵn là cấp hiện tại (Đất nền – Sở hữu) nên nút 'NÂNG CẤP CÔNG TRÌNH' xám, không có hướng dẫn. Icon Khách sạn là khối vàng placeholder; badge 'ĐÃ XÂY' đè lên icon cờ. | F21: Mặc định chọn cấp kế tiếp; hiển thị 'Tiền thuê: 32k → 160k'. Thay icon khách sạn; badge đặt góc thẻ. | H21: Đã quan sát | I21: Chưa làm
A22: UI-07 | B22: Giao diện (UI/UX) | C22: Luật chơi và UI không khớp | D22: P2 | E22: Luật: Đất trống → Nhà cấp 1 → Nhà cấp 2 → Biệt thự → Siêu Resort 5 sao (5 cấp). UI: Đất nền → Nhà phố → Chung cư → Khách sạn/Landmark (4 cấp). Trang giới thiệu ghi '28 danh lam thắng cảnh' nhưng chỉ có 16 ô địa danh. Linh vật ở sảnh 'Heo Phượt/Cáo Tí' nhưng trong game là 'Kỳ Thủ Nhí/Bot Tí Nị'. | F22: Thống nhất 1 bộ tên cấp nhà, số địa danh, tên linh vật trên toàn bộ: Luật, modal, nhật ký, trang giới thiệu. | H22: Đã kiểm chứng | I22: Chưa làm
A23: UI-08 | B23: Giao diện (UI/UX) | C23: Thông báo thẻ & nhật ký chưa thân thiện | D23: P3 | E23: Thẻ di chuyển ghi 'Bay thẳng tới ô #31' (lộ số index). Nhật ký thuê 'trả tiền thuê 25.000đ cho chủ nhà' không nêu tên chủ. Lỗi chính tả 'ĐỔI ĐÔI!' (đúng: 'ĐỔ ĐÔI!'). Văn phong lẫn lộn 'đầu tư thành công … lên [Đất nền]' và 'mua thành công bất động sản'. | F23: Hiện tên ô thay số; ghi rõ 'trả 25.000đ cho Bot Tí Nị'; sửa chính tả; thống nhất văn phong nhật ký. | H23: Đã kiểm chứng | I23: Chưa làm
A24: UI-09 | B24: Giao diện (UI/UX) | C24: Nội dung thẻ không hợp thương hiệu 'Tuổi Thơ' | D24: P2 | E24: Luật mô tả thẻ 'bị CSGT phạt vi phạm nồng độ cồn' — không phù hợp game hướng tới trẻ em/gia đình. | F24: Rà soát toàn bộ bộ thẻ Cơ Hội/Khí Vận, thay bằng tình huống lành mạnh (quên đội mũ bảo hiểm, đi học muộn, trúng giải vẽ tranh…). | H24: Đã đọc trong Luật chơi | I24: Chưa làm
A25: UI-10 | B25: Giao diện (UI/UX) | C25: Bố cục nhảy khi mở/đóng panel | D25: P2 | E25: Mở rộng Nhật ký → panel xúc xắc nhảy xuống; mở Chat → nút cảm xúc đổi vị trí (bấm trượt). | F25: Các panel có vị trí neo cố định, không đẩy nhau. | H25: Đã quan sát | I25: Chưa làm
A26: UI-11 | B26: Giao diện (UI/UX) | C26: Lỗi nhỏ: icon & accessibility | D26: P3 | E26: Nút 'Luật Chơi' hiển thị cả icon sách và emoji 📖 bị vỡ thành ô vuông trắng. 1 nút icon không có aria-label. Chat trong chế độ đấu Bot gần như không có tác dụng. | F26: Bỏ emoji trong nút, dùng 1 icon SVG. Thêm aria-label cho mọi nút icon. Ẩn Chat khi chơi với Bot hoặc cho Bot phản hồi câu nói nhanh. | H26: Đã kiểm chứng | I26: Chưa làm
A27: VIS-01 | B27: Đồ họa 3D | C27: Đường kẻ trắng lạ cắt ngang bàn cờ | D27: P1 | E27: Một khung vuông viền trắng rất lớn, nghiêng, nổi trên bàn cờ, cắt qua các ô và cả HUD; xoay camera vẫn thấy. | F27: Xóa hoàn toàn. Nhiều khả năng là helper (LineLoop/BoxHelper/camera helper) hoặc đường path debug còn sót lại. | G27: Tìm LineSegments/LineLoop/*Helper trong scene; tắt mọi debug helper ở build production. | H27: Đã quan sát ở mọi góc nhìn | I27: Chưa làm
A28: VIS-02 | B28: Đồ họa 3D | C28: Cảnh trang trí trung tâm che bàn cờ và quân | D28: P1 | E28: Cụm núi đá cao ở giữa che hàng ô phía trên (các ô tím, Thành Phố Hoa Đà Lạt, Cầu Rồng…); quân Bot đứng ở Cầu Rồng không nhìn thấy. Vật thể nâu hình bán trụ ở giữa nhìn như mesh lỗi. | F28: Hạ thấp/thu nhỏ núi, đặt lệch về tâm, không được cao quá mặt phẳng nhìn tới hàng ô xa. Thay vật thể nâu bằng mô hình có nghĩa (thuyền, mái đình…). Tiêu chí: ở góc nhìn mặc định 100% ô và quân đều thấy. | H28: Đã quan sát | I28: Chưa làm
A29: VIS-03 | B29: Đồ họa 3D | C29: Góc camera mặc định cắt mất góc Cổng Làng | D29: P1 | E29: Góc dưới (ô Xuất Phát/Cổng Làng, giá Đất Mũi Cà Mau) bị cắt khỏi khung hình. | F29: Camera mặc định thấy trọn 4 góc bàn cờ; thêm nút 'Đặt lại góc nhìn' và 2–3 preset (Toàn cảnh / Theo quân / Từ trên xuống). | H29: Đã quan sát | I29: Chưa làm
A30: VIS-04 | B30: Đồ họa 3D | C30: Quân cờ không ra hình linh vật, khó nhìn | D30: P1 | E30: Quân là khối tròn hồng-xanh và khối cam, không giống heo/cáo như avatar; tên trên đầu chữ cam rất nhỏ; 2 quân cùng ô thì chồng lên nhau và che tên ô. | F30: Mô hình chibi low-poly đúng 4 linh vật (Heo, Cáo, Mèo, Trâu), có viền/vòng sáng màu người chơi dưới chân, tên dạng badge dễ đọc. Nhiều quân cùng ô thì xếp lệch vị trí. | G30: Có thể dùng model GLB miễn phí (Kenney, Quaternius) hoặc dựng từ primitive nhưng có tai/mõm đặc trưng. | H30: Đã quan sát | I30: Chưa làm
A31: VIS-05 | B31: Đồ họa 3D | C31: Vật thể 3D đè lên chữ ở ô góc và ô thẻ | D31: P2 | E31: 'TRẠI G…' bị mô hình xe cảnh sát đè; 'LỄ H…' bị hộp quà đè; 'Khí Vậ…' bị khối tím đè; chữ 'Vịnh Biển Nha Trang' xuống dòng lỗi 'Tran/g'. | F31: Đặt vật thể sang một bên hoặc đặt chữ lên trên; dùng text có wrap đúng theo từ. | H31: Đã quan sát | I31: Chưa làm
A32: VIS-06 | B32: Đồ họa 3D | C32: Đạo cụ placeholder & xúc xắc thừa | D32: P2 | E32: Chồng thẻ Cơ Hội/Khí Vận là khối lập phương màu cam/tím lơ lửng với bóng xám vuông; trên bàn có thêm 2–3 viên xúc xắc trắng nằm rải rác ngoài 2 viên đang dùng. | F32: Thay bằng chồng lá bài có in biểu tượng; xóa xúc xắc thừa (hoặc giải thích là trang trí). | H32: Đã quan sát | I32: Chưa làm
A33: VIS-07 | B33: Đồ họa 3D | C33: Giá và màu nhóm ô khó đọc | D33: P2 | E33: Giá in chữ cam nhỏ, tương phản thấp, vị trí không đều (có giá nằm ra mép giữa 2 ô). Dải màu nhóm khó phân biệt (nhiều sắc xanh dương gần giống nhau), không có chú thích miền. | F33: Giá in đậm trong khung cố định ở cạnh ngoài ô; 8 nhóm màu tách bạch (tham chiếu bảng màu Monopoly); thêm chú thích miền Bắc/Trung/Nam/Biển đảo. | H33: Đã quan sát – nhóm màu cần dev đối chiếu config | I33: Chưa làm
A34: VIS-08 | B34: Đồ họa 3D | C34: Phong cách tổng thể chưa đồng bộ, thiếu 'chất Đảo Ngọc' | D34: P2 | E34: Cảnh low-poly 3D + HUD tối kiểu dashboard + modal kem sáng → 3 phong cách khác nhau. Nền là khoảng xám trống, khung bàn nâu trơn, ánh sáng phẳng. Không có tài sản 3D (không tải file .glb nào) – toàn bộ dựng từ khối cơ bản. | F34: Chọn 1 art direction: đảo nhiệt đới nổi trên biển (nước có shader sóng nhẹ, mây, bầu trời gradient), khung bàn gỗ có hoa văn, ánh sáng chiều ấm + bóng mềm. HUD và modal dùng chung 1 bảng màu/bo góc/font. | H34: Đã quan sát | I34: Chưa làm
A35: VIS-09 | B35: Đồ họa 3D | C35: Điều khiển camera chưa tốt | D35: P2 | E35: Kéo chuột ~200px đã xoay gần 90° (quá nhạy); cuộn chuột không zoom; không có nút đặt lại góc nhìn. | F35: Giảm rotateSpeed, giới hạn góc polar/azimuth, bật zoom có min/max, thêm nút reset; trên mobile hỗ trợ pinch. | G35: OrbitControls: rotateSpeed≈0.4, enableZoom=true, minDistance/maxDistance, damping. | H35: Đã kiểm chứng | I35: Chưa làm
A36: ANI-01 | B36: Animation | C36: Đổ xúc xắc chưa có cảm giác | D36: P1 | E36: Xúc xắc 3D nhỏ, nằm xa giữa bàn, gần như không thấy lăn; kết quả hiện ở 2 nơi (banner + panel). | F36: Xúc xắc lăn to ở gần camera (vật lý hoặc tween xoay 0,8–1,2s), nảy nhẹ, dừng → số nổi lên → âm thanh 'cạch'. Đổ đôi có hiệu ứng riêng. | G36: cannon-es/rapier hoặc tween quaternion tới mặt kết quả định trước. | H36: Đã quan sát | I36: Chưa làm
A37: ANI-02 | B37: Animation | C37: Di chuyển quân & camera | D37: P1 | E37: Không quan sát rõ quân nhảy từng ô; camera không bám theo; quân bị khuất sau núi/HUD. Thẻ di chuyển (bay tới ô) không có hiệu ứng bay. | F37: Quân nhảy từng ô (0,15–0,25s/ô, có squash & stretch), camera bám theo mượt rồi trả về toàn cảnh. Thẻ 'bay' có quỹ đạo vòng cung + máy bay/đám mây. | H37: Cần dev kiểm tra thêm | I37: Chưa làm
A38: ANI-03 | B38: Animation | C38: Không có phản hồi khi tiền thay đổi | D38: P2 | E38: Mua đất, trả thuê, qua Cổng Làng, ăn Quỹ Heo: số dư chỉ đổi số im lặng. | F38: Số nổi +200k/−25k cạnh thẻ người chơi, đồng xu bay từ người trả sang người nhận, số dư đếm lên/xuống. Ăn Quỹ Heo: heo đất vỡ + xu tung. | H38: Đã quan sát | I38: Chưa làm
A39: ANI-04 | B39: Animation | C39: Mua/nâng cấp không có hiệu ứng trên bàn | D39: P1 | E39: Sau khi mua/nâng cấp không có gì xuất hiện trên ô (liên quan UI-02). | F39: Mua: cắm cờ rơi xuống ô. Nâng cấp: nhà mọc lên (scale 0→1, bụi/sparkle). Lên Khách sạn/Landmark: pháo hoa nhỏ. | H39: Đã kiểm chứng | I39: Chưa làm
A40: ANI-05 | B40: Animation | C40: Rút thẻ Cơ Hội/Khí Vận | D40: P2 | E40: Modal thẻ bật thẳng ra, hình minh họa là emoji chung (💰, ✈️, 🗝️). | F40: Lá bài bay ra từ chồng thẻ trên bàn, lật mặt 3D, mỗi thẻ có minh họa riêng theo chủ đề Việt Nam. | H40: Đã quan sát | I40: Chưa làm
...

Sheet Chưa kiểm tra
A1: Hạng mục | B1: Lý do / việc cần test
A2: Giao diện mobile / tablet | B2: Không resize được cửa sổ trình duyệt trong phiên review. Cần test 390×844 và 768×1024: HUD, modal, điều khiển chạm.
A3: Chế độ Online P2P (WebRTC, mã PIN) | B3: Cần 2 thiết bị. Kiểm tra đồng bộ trạng thái, mất kết nối, người chơi thoát giữa ván.
A4: Vào tù / ra tù / Kim Bài Thoát Tù | B4: Trong ~13 lượt chơi chưa ai vào Trại Giam.
A5: Phá sản & kết thúc ván | B5: Chưa chạm tới. Cần test: thiếu tiền trả thuê → bắt buộc bán/thế chấp → phá sản → màn hình chiến thắng.
A6: Âm thanh (nhạc nền, hiệu ứng) | B6: Game không tải file âm thanh (có thể tạo bằng Web Audio). Không đánh giá được chất lượng âm thanh.
A7: Hiệu năng | B7: Máy review: ~59 FPS, tải ~461 KB, RAM JS ~76 MB → tốt. Cần test trên điện thoại tầm trung.
